# `@ryact-utils/attempt`

A feather‚Äëweight, type‚Äësafe wrapper that turns _anything_‚Äîfunctions, promises, or raw values‚Äîinto a predictable **result tuple** \`[error, data, ok]\`.

It ships with:

- A **pre‚Äëconfigured helper**¬†`attempt`
- A factory¬†`createAttempt`¬†for custom error coercion
- Low‚Äëlevel utilities¬†`createResult`¬†and¬†`DEFAULT_COERCE_ERROR`

---

## Installation

```bash
npm i @ryact-utils/attempt
# or
yarn add @ryact-utils/attempt
```

---

## Glossary

| Term              | Meaning                                                                                                                                        |
| ----------------- | ---------------------------------------------------------------------------------------------------------------------------------------------- |
| **AttemptResult** | The tuple \`[error, data, ok]\` returned by any wrapper. It also carries twin properties:<br>\`result.error\`, \`result.data\`, \`result.ok\`. |
| **Success**       | \`ok === true\`, \`error === undefined\`, and \`data\` holds the value.                                                                        |
| **Failure**       | \`ok === false\`, \`error\` holds the coerced error, and \`data === undefined\`.                                                               |

---

## Quick Example: From nested `try / catch` hell to clean `attempt` flow

### The old way (try/catch hell)

```ts
async function loadDashboard(userId: string) {
	try {
		const user = await fetchUserById(userId);
		try {
			const posts = await fetchPostsForUser(user.id);
			try {
				const comments = await fetchCommentsForPost(posts[0].id);
				console.log({ user, posts, comments });
			} catch (e) {
				console.error('Comments step failed:', e);
			}
		} catch (e) {
			console.error('Posts step failed:', e);
		}
	} catch (e) {
		console.error('User step failed:', e);
	}
}
```

### The `attempt` way (flat & readable)

```ts
// flat-flow.ts
async function loadDashboard(userId: string) {
	const [uErr, user] = await attempt(fetchUser(userId));
	if (uErr) return console.error(uErr);

	const [pErr, posts] = await attempt(fetchPosts(user.id));
	if (pErr) return console.error(pErr);

	const [cErr, comments] = await attempt(fetchComments(posts[0].id));
	if (cErr) return console.error(cErr);

	console.log({ user, posts, comments });
}
```

With `attempt`, every operation is wrapped in a single line, making the happy path obvious and the error handling explicit‚Äîwithout ever nesting `try / catch` blocks.

#### Improvements:

- ‚úÖ One level of indentation throughout
- ‚úÖ Linear sequence‚Äîhandle each error in place, then move on
- ‚úÖ Success path reads top-to-bottom like a recipe

---

## API Reference

### 1. `attempt(thing, ...args)`

**Universal dispatcher.**

| Argument  | Accepts                                                                      | Action taken                      |
| --------- | ---------------------------------------------------------------------------- | --------------------------------- |
| `thing`   | ‚Ä¢ A **function** (sync or async)<br>‚Ä¢ A **Promise**<br>‚Ä¢ Any other **value** | Runs / awaits / wraps accordingly |
| `...args` | Parameters forwarded when `thing` is a function                              | ‚Äî                                 |

Returns either an `AttemptResult` or `Promise<AttemptResult>` depending on whether `thing` ends up async.

#### Usage

```ts
// Sync function
attempt(Math.sqrt, 9);
attempt(() => Math.sqrt(9));

// Function that returns a promise
await attempt(() => fetch('/api').then((r) => r.json()));
await attempt(someAsyncFn, param1, param2);

// Promise
await attempt(someAsyncFn(param1, param2));
await attempt(Promise.resolve('success'));

// Raw value
attempt(123);
```

---

### 2. `attempt.sync(fn, ...args)`

Executes a **synchronous** function in a `try / catch`.

```ts
const res = attempt.sync(parseInt, '42');

// or

const res = attempt.sync(() => parseInt('42'));
```

---

### 3. `attempt.async(fn, ...args)`

Runs an **async** function (one that _returns_ a promise) and awaits it.

```ts
const res = await attempt.async(readFile, 'config.json');

// or

const res = await attempt.async(() => readFile('config.json'));
```

---

### 4. `attempt.promise(promise)`

Wraps an _existing_ promise.

```ts
const res = await attempt.promise(fetch('/api'));
```

---

### 5. `attempt.fn(fn, ...args)`

Alias for the ‚Äúsmart‚Äù branch used internally by `attempt(...)`.  
Useful when you explicitly want ‚Äúfunction mode‚Äù:

```ts
const res = attempt.fn(mightBeAsync, 1, 2, 3);

// or

const res = attempt.fn(() => mightBeAsync(1, 2, 3));
```

---

### 6. `attempt.any(valueOrFnOrPromise, ...args)`

Identical to the top‚Äëlevel `attempt`. Provided for symmetry and readability when you‚Äôve created a _custom_ attempt instance (see below).

---

### 7. `createAttempt(coerceError)`

Builds a **customised** attempt helper whose `.error` slot always conforms to _your_ shape.

| Param         | Purpose                                                                             |
| ------------- | ----------------------------------------------------------------------------------- |
| `coerceError` | `(x: unknown) ‚Üí MyErrorType` ‚Äî convert anything thrown into a domain‚Äëspecific error |

```ts
import { createAttempt } from '@ryact-utils/attempt';

const toAxiosError = (x: unknown) =>
	x && typeof x === 'object' && 'isAxiosError' in x ? x : { message: String(x) };

// reusable custom attempt
export const axiosAttempt = createAttempt(toAxiosError);

const res = await axiosAttempt(axios.get('/users'));
```

All methods (`sync`, `async`, `promise`, `fn`, `any`) are available on the returned instance.

---

### 9. `DEFAULT_COERCE_ERROR`

The built‚Äëin coercion logic used by the default `attempt`.

1. **`Error`** instances pass through unchanged.
2. **Strings** become `Error(string)`.
3. Everything else becomes `Error("Unknown error caught with \"attempt\"", { cause })`.

You can re‚Äëuse it when composing your own coercer:

```ts
import { createAttempt, DEFAULT_COERCE_ERROR } from '@ryact-utils/attempt';

const attemptPlus = createAttempt((x) => ({
	original: DEFAULT_COERCE_ERROR(x), // keep stack trace
	timestamp: Date.now(),
}));
```

### 10. `AttemptResult` ‚Äî Type Signature Breakdown

`AttemptResult<TReturn, TError>` is a **tagged union** that captures *either* a success *or* a failure in a single, tuple-shaped value.
It comes in two variants:

```ts
// ‚úÖ SUCCESS
type AttemptSuccess<TReturn> = [
  undefined,   // error slot is always undefined
  TReturn,     // the data you asked for
  true         // explicit success flag
] & {
  error:   undefined;
  data:    TReturn;
  success: true;
};

// ‚ùå FAILURE
type AttemptFailure<TError> = [
  TError,      // the coerced error
  undefined,   // data is undefined
  false        // explicit failure flag
] & {
  error:   TError;
  data:    undefined;
  success: false;
};

// üì¶ Combined
type AttemptResult<TReturn, TError> =
  | AttemptSuccess<TReturn>
  | AttemptFailure<TError>;
```

### Tuple Indices vs. Named Properties

| Position | Named property | Meaning                                                  |
| -------- | -------------- | -------------------------------------------------------- |
| `[0]`    | `.error`       | The error object on failure, or `undefined` on success.  |
| `[1]`    | `.data`        | The returned data on success, or `undefined` on failure. |
| `[2]`    | `.ok`     | A boolean you can use to narrow the union in TypeScript in the case where TError or TReturn can be falsy. |

Because each variant hard-codes `true` or `false` in the third slot, TypeScript‚Äôs control-flow analyzer automatically narrows types inside an `if (result.success)` block:

```ts
const result = await attempt.async(fetchUser, "123");

if (result.ok) {
  // TS knows: result.data is User; result.error is undefined
  console.log(result.data.name);
} else {
  // TS knows: result.error is Error; result.data is undefined
  console.error(result.error.message);
}
```

### Generic Parameters

* `TReturn` ‚Äî the type of the successful value (inferred from your function or promise).
* `TError`  ‚Äî the type of the coerced error (defaults to `unknown`, but becomes whatever you supply via `createAttempt(coerceError)`).

---

**Why a tuple *and* properties?**
The tuple form makes destructuring concise:

```ts
const [err, value, ok] = await attempt.promise(fetch("/api"));
```

while the object properties give self-documenting clarity when that fits your style:

```ts
if (!result.ok) return result.error;
return doSomething(result.data);
```

---

## FAQ

**Does it replace exceptions?**  
No‚Äîyou can still `throw` if you prefer. `attempt` simply gives you the option to treat errors as data when that feels cleaner.

**Tree‚Äëshakeable?**  
Yes. ES modules, no external dependencies.

**Browser support?**  
Any runtime that supports ES2019. For older targets, polyfill or down‚Äëcompile.

**Size?**  
&lt;¬†0.5¬†kB gzipped.

---

## License

MIT
